Workbook

Sheet Data2023
A1: CTY CP LAI TRƯỜNG SƠN | F1: =TODAY() -> 46094 | H1: CƠ SỞ TÍNH GIÁ BÁN TÚI | K1: =(40*2.1+79*1.4)+120 -> 314.6 | M1: LỢI NHUẬN CHO KHÁCH HÀNG SEN VIỆT và LƯƠNG GIA
M2: KHÁCH HÀNG KHÁC thì LN + 3%
A3: GIÁ NGUYÊN LIỆU CẬP NHẬT HÀNG NGÀY ****THÙY và TRANG**** | H3: CHI PHÍ SẢN XUẤT | I3: Sản lượng tháng | J3: Chi Phí | K3: Tổng chi phí 2023 | M3: Giá Vốn | N3: Túi 3,4 biên, màng ghép: 2 lớp | O3: Túi zipper, Đáy đứng, MPET,AL, giấy, màng ghép 3 lớp.. | Q3: CHI PHÍ SẢN XUẤT
A4: Stt | B4: MÀNG | C4: Tỉ trọng | D4: Độ dầy | E4: Giá(Chua Vat) | H4: CPSX IN + CHIA | I4: 1600000 | J4: =V12 | K4: =J4/I4 -> 0 | M4: dưới 9,9tr | N4: 0.5 | O4: 0.8 | Q4: Chi Phí chung | R4: Số lượng | S4: Chi Phí | T4: Tổng chi phí
C5: (gr/m2) | D5: mic | E5: vnd/ kg | F5: vnd/m2 | H5: CPSX GHÉP L1 | I5: 500000 | J5: =V21 | K5: =J5/I5+K1 -> 314.6 | M5: 10.000.000-19.000.000 | N5: =22% -> 0.22 | O5: 0.42 | Q5: Kế Toán trưởng | R5: 1 | S5: 22000000 | T5: =S5*R5 -> 22000000
A6: 1 | B6: PET | C6: 1.4 | D6: 12 | E6: =(35000+2500)/1.1 -> 34090.909 | F6: =E6*D6*C6/1000 -> 572.72727 | H6: CPSX GHÉP L2 | I6: 300000 | J6: =J5 | K6: =J6/I6+K1 -> 314.6 | M6: 20.000.000-30.000.000 | N6: 0.17 | O6: 0.27 | Q6: Bảo vệ | R6: 2 | S6: 7000000 | T6: =S6*R6 -> 14000000
A7: 2 | B7: PA | C7: 1.16 | D7: 15 | E7: 70000 | F7: =E7*D7*C7/1000 -> 1218 | H7: CPSX CẮT L1 | I7: 500000 | J7: =V28 | K7: =J7/I7 -> 0 | M7: 31.000.000-40.000.000 | N7: 0.11 | O7: 0.2 | Q7: Thủ kho + xe nâng | R7: 2 | S7: 15000000 | T7: =S7*R7 -> 30000000
A8: 3 | B8: MPET | C8: 1.4 | D8: 12 | E8: =45000/1.1 -> 40909.091 | F8: =E8*D8*C8/1000 -> 687.27273 | H8: CPSX CẮT L2 | I8: =I7*0.6 -> 300000 | J8: =J7 | K8: =J8/I8 -> 0 | M8: 41.000.000-60.000.000 | N8: 0.08 | O8: 0.19 | Q8: Tài xế xe tải + dầu | R8: 1 | S8: 25000000 | T8: =S8*R8 -> 25000000
A9: 4 | B9: CPP 25 | C9: 0.92 | D9: 25 | E9: =45000/1.1 -> 40909.091 | F9: =E9*D9*C9/1000 -> 940.90909 | K9: =VLOOKUP(E9,Data2023!$B$6:$F$24,5,0) -> #N/A | M9: 61.000.000-80.000.000 | N9: 0.08 | O9: 0.18 | Q9: CP Quan Li+CP khac | R9: 1 | S9: 100000000 | T9: =S9*R9 -> 100000000
A10: 5 | B10: CPP 50 | C10: 0.92 | D10: 50 | E10: =45000/1.1 -> 40909.091 | F10: =E10*D10*C10/1000 -> 1881.8182 | M10: 81.000.000-100.000.000 | N10: 0.075 | O10: 0.17 | Q10: Kinh doanh | R10: 5 | S10: 13000000 | T10: =S10*R10 -> 65000000
B11: CPP 50 | C11: 0.92 | D11: 50 | E11: =45000/1.1 -> 40909.091 | F11: =E11*D11*C11/1000 -> 1881.8182
A12: 6 | B12: LLDPE | C12: 0.925 | D12: 120 | E12: 40000 | F12: =E12*D12*C12/1000 -> 4440 | H12: Vận chuyển (bán kính trên 30km) : khách 50%,cty 50% | M12: 101.000.000-150.000.000 | N12: 0.07 | O12: 0.16 | Q12: CPSX MÁY IN + CHIA | R12: =I4 -> 1600000 | S12: =ROUND(T12/R12,0) -> 318 | T12: =SUM(T13:T20) -> 5.0892381e+08
A13: 7 | B13: LLDPE sữa | C13: 0.925 | D13: 0 | E13: 40000 | F13: =E13*D13*C13/1000 -> 0 | H13: Chi phí thùng giấy : tính giá thùng chia cho số túi trong thùng | M13: 151.000.000-200.000.000 | N13: 0.07 | O13: 0.16 | Q13: Quản lí | R13: 1 | S13: 15000000 | T13: =R13*S13 -> 15000000
A14: 8 | B14: AL | C14: 2.76 | D14: 6 | E14: =122000/1.1 -> 110909.09 | F14: =E14*D14*C14/1000 -> 1836.6545 | H14: Lãi vay : Lãi vay 0.85%/ 30 ngày, nếu tt quá hạn n+30 ngày thì trừ tiền hoa hồng của sale | M14: 300000000 | N14: 0.06 | O14: 0.15 | Q14: Thợ | R14: 2 | S14: 20000000 | T14: =R14*S14 -> 40000000
A15: 9 | B15: Bopp 18 mic | C15: 0.91 | D15: 18 | E15: =45500/1.1 -> 41363.636 | F15: =E15*D15*C15/1000 -> 677.53636 | H15: Hoa Hồng bán hàng : tính vào giá bán tối đa 5%, nếu vượt quá 5% phải có cấp trên đồng ý | M15: 400000000 | N15: 0.05 | O15: 0.15 | Q15: Phụ | R15: 8 | S15: 12000000 | T15: =R15*S15 -> 96000000
A16: 10 | B16: Bopp 20 mic | C16: 0.91 | D16: 20 | E16: =45500/1.1 -> 41363.636 | F16: =E16*D16*C16/1000 -> 752.81818 | H16: Chi phí dây zipper: tính theo phi hao máy cắt | M16: 500000000 | N16: 0.05 | O16: 0.15 | Q16: Mặt bằng | R16: 1000 | S16: 60000 | T16: =R16*S16 -> 60000000
A17: 11 | B17: Bopp 30 mic | C17: 0.91 | D17: 30 | E17: 40000 | F17: =E17*D17*C17/1000 -> 1092 | H17: Màng PE cho túi Gạo 3 biên và 4 biên dưới 4kg : sử dụng loại PE thường | M17: 600000000 | N17: 0.04 | O17: 0.14 | Q17: Khau hao máy 5ty/84 thang | R17: 84 | S17: 5000000000 | T17: =S17/R17 -> 59523810
A18: 12 | B18: Matt BOPP 20mic | C18: 0.88 | D18: 20 | E18: =55000/1.1 -> 50000 | F18: =E18*D18*C18/1000 -> 880 | H18: Hoa hồng được tính sau khí khách trả tiền | M18: 700000000 | N18: 0.04 | O18: 0.13 | Q18: Điện | R18: =R12 -> 1600000 | S18: 70 | T18: =R18*S18 -> 112000000
A19: 13 | B19: Màng ngọc 30-40 | C19: 0.604 | D19: 40 | E19: =70000/1.1 -> 63636.364 | F19: =E19*D19*C19/1000 -> 1537.4545 | H19: GIÁ NGUYÊN LIỆU ( Cập nhật theo thời điểm tính giá), Thuy cập nhật giá vào file nầy 1 tuần 1 lần vào sáng thứ 2 | M19: 800000000 | N19: 0.04 | O19: 0.12 | Q19: Phụ chia | R19: 2 | S19: 12000000 | T19: =R19*S19 -> 24000000
A20: 14 | B20: Màng ngọc 60-110 | C20: 0.604 | D20: 60 | E20: 73000 | F20: =E20*D20*C20/1000 -> 2645.52 | M20: 900000000 | N20: 0.04 | O20: 0.12 | Q20: Phan Bo CP chung | R20: 0.4 | S20: =SUM(T5:T10) -> 256000000 | T20: =R20*S20 -> 102400000
A21: 15 | B21: MCPP 25 | C21: 0.91 | D21: 25 | E21: 49000 | F21: =E21*D21*C21/1000 -> 1114.75 | M21: 1000000000 | N21: 0.04 | O21: 0.11 | Q21: CPSX MÁY GHÉP | R21: =I5 -> 500000 | S21: =T21/R21 -> 346.01905 | T21: =SUM(T23:T27) -> 1.7300952e+08
A22: 17 | B22: Matt BOPP 20mic | C22: 0.88 | D22: 20 | E22: 50000 | F22: 0
A23: 16 | B23: Zipper | E23: =360*1.05 -> 378 | M23: 1100000000 | N23: 0.04 | O23: 0.1 | Q23: Thợ | R23: 1 | S23: 20000000 | T23: =R23*S23 -> 20000000
A24: 18 | B24: 0 | C24: 0 | D24: 0 | E24: 0 | F24: 0 | Q24: Khau hao | R24: 84 | S24: 2000000000 | T24: =S24/R24 -> 23809524
E25: Chỉ nhập giá vào cột E | Q25: Mặt bằng | R25: 500 | S25: 60000 | T25: =R25*S25 -> 30000000
B26: Nhập thêm từ hàng 25 | Q26: Điện | R26: 400000 | S26: 120 | T26: =R26*S26 -> 48000000
Q27: Phan Bo CP chung | R27: 0.2 | S27: =S20 -> 256000000 | T27: =R27*S27 -> 51200000
B28: TRANG CHỈ SỬA TRÊN FILE TÍNH GIÁ CỦA TRANG TRONG BẢNG TÍNH - tỉ trọng màng ngọc sai (đang dùng của sanchao 0,604) - chỗ ghép lần 2 thêm giá trị 0 => cảnh báo chứ ko bắt buộc ko cho nhập gt khác (đã sửa) - chi phí sản xuất in sai: giá OPP in cao hơn PET đã sửa lại: =C50*IF(E46="PET 12";135;if(E46="PA 15";135;120))*C56+318+C51 - cột lợi nhuận áp sai: túi ko phải zipper nhưng áp cột ln zipper dành cho SV và LG => lợi nhuận cột 1 hoặc 2 dành cho túi thường /zip: cột 1: bấm số 1,cột 2: bất kỳ - bổ sung giá màng ngọc + băng keo trong cột giá màng (đã tự bổ sung) -chi phí zipper không được tính trong chỗ giá vốn sản phẩm? Em có tính 2 bảng so sánh giá chỉ cần nhập số lượng 30,000 ,40.000, 60,000, 80,000, 100.000 hoặc 150.000 hoặc bất kì -đã cài lại công thức giá trục chu vi tối đa 5 con hình, giá trục bán ra đang để 7tr3, bỏ giá trục in/số túi ra khỏi giá bán túi -vận chuyển chưa thấy để số km vào nếu giao hàng tỉnh xa cty thiệt hại. -chỗ thành tiền màng => giá màng VNĐ/m2 | Q28: CPSX MÁY CẮT | R28: =I7 -> 500000 | S28: =T28/R28 -> 712.22857 | T28: =SUM(T29:T35) -> 356114286
Q29: Thợ chính | R29: 1 | S29: 20000000 | T29: =S29*R29 -> 20000000
Q30: Thợ phụ | R30: 1 | S30: 16000000 | T30: =S30*R30 -> 16000000
Q31: Phụ | R31: 10 | S31: 10000000 | T31: =S31*R31 -> 100000000
Q32: Khau hao | R32: 84 | S32: 3000000000 | T32: 35714286
Q33: Điện cắt | R33: 400000 | S33: 130 | T33: =R33*S33 -> 52000000
Q34: Mặt bằng | R34: 500 | S34: 60000 | T34: 30000000
Q35: Phan Bo CP chung | R35: 0.4 | S35: =S20 -> 256000000 | T35: =S35*R35 -> 102400000
B46: TRANG: bất cập: giá bao bì biến động liên tục, nếu chỉ dùng 1 bảng data 2023: giá túi đã mua vật tư sx xong, nhưng thay đổi để tính 1 loại khác có cùng chất liệu => giá túi đã sx xong cũng thay đổi theo.
B48: 21/03/2023 TRANG
B49: KHÔNG CÓ TÍNH GIÁ CHO 2 CON HÌNH / 3 CON HÌNH
B50: TRỌNG LƯỢNG CHỈ DỰA VÀO TỈ TRỌNG MÀNG PE CHỨ KO PHẢI THEO TỈ TRỌNG CÁC LOẠI MÀNG
B51: THÊM DÒNG GIÁ PE CHO NCC VĨNH PHÁT / BNC
...

Sheet TRANG
A1: TRANG
A3: Ngày báo giá
I56: <50000m | J56: >50000
G57: mafu | H57: set up
G58: 8 | H58: 1800 | I58: mafng TP/6000*40 | J58: +tp/50000*400
G59: 7 | H59: 1700 | I59: nt | J59: nt
G60: 6 | H60: 1500 | I60: nt | J60: nt
G61: 5 | H61: 1200 | I61: nt | J61: nt
D62: =215+50 -> 265 | G62: 4 | H62: 1000 | I62: nt | J62: nt
D63: =D62*2 -> 530 | G63: 3 | H63: 800 | I63: nt | J63: nt
G64: 2 | H64: 500 | I64: nt | J64: nt
B65: kích thước | C65: R145 x (D215 +Đ 50) | G65: 1 | H65: 400 | I65: nt | J65: nt
A66: Khách hàng | B66: a | C66: Khổ trãi | D66: Bước cắt | E66: Diện tích 1 túi m2 | F66: Tổng DT đơn hàng | G66: Khổ màng in thành phẩm | H66: Dài màng thành phẩm | I66: Giá vốn | J66: Truc in | K66: Zipper | L66: Thùng giấy | M66: Vận chuyển | N66: Lãi vay | O66: Hoa hồng | P66: Giá cuối | Q66: Giá bán chốt | S66: < | T66: 31000000 | U66: 0.17 | V66: =U66+3% -> 0.2 | W66: 0.27 | X66: 0.3
A67: Tên hàng | B67: ab | C67: m | D67: m | E67: m2 | F67: m2 | G67: m | H67: m | I67: túi | J67: =G76 -> 2222850 | K67: =(G73+H73)*B7 -> 0 | N67: =G79 -> 0.0082191781 | O67: =E80 -> 0 | P67: Chưa VAT | Q67: =P64 | S67: < | T67: 41000000 | U67: 0.11 | V67: =U67+3% -> 0.14 | W67: 0.2 | X67: 0.23
A68: Số lượng TP | B68: 30000 | C68: 0.53 | D68: =B73 -> 0.145 | E68: =C68*D68 -> 0.07685 | F68: =B68*E68 -> 2305.5 | G68: =IF(C68>0.4,C68,C68*2) -> 0.53 | H68: =D68*B68 -> 4350 | I68: =O70/B68 -> 670.3595 | K68: =D68*360 -> 52.2 | L68: =20000/2000 -> 10 | M68: =30*20000/B68 -> 20 | N68: =G79*I68 -> 5.5098041 | O68: 50 | P68: =SUM(I68:O68) -> 808.0693 | Q68: 820 | S68: < | T68: 81000000 | U68: 0.08 | V68: =U68+3% -> 0.11 | W68: 0.19 | X68: 0.21
A69: Cấu trúc | B69: PET12//PE120 | C69: HẠN MỤC CPSX | D69: MÀNG NL | E69: Độ dầy | F69: Khổ màng | G69: Số mét bán TP | H69: Phi hao | I69: Giá màng vnd/kg | J69: Thành tiền màng (vnd/m2) | K69: Chi phí sản xuất | L69: Thành tiền CPSX | M69: Giá màng In và ghép | N69: Giá vốn | O69: Tổng giá vốn | P69: LN | Q69: Doanh Thu | S69: < | T69: 101000000 | U69: 0.075 | V69: =U69+3% -> 0.105 | W69: 0.18 | X69: 0.2
A70: Độ dầy (mic) | B70: 135 | C70: CPSX IN | D70: PET | E70: =VLOOKUP(D70, Data2023!$B$6:$F$23, 3, FALSE) -> 12 | F70: 0.55 | G70: =G72+H72 -> 4608.86 | H70: =IF(B74=8,1800,IF(B74=7,1700,IF(B74=6,1500,IF(B74=5,1200,IF(B74=4,1000,IF(B74=3,800,IF(B74=2,500,400)))))))+(G70/6000*40)+IF(G70>50000,G70/50000*400,0) -> 1030.7257 | I70: =VLOOKUP(D70,Data2023!$B$6:Data2023!$F$22,4,0) -> 34090.909 | J70: =VLOOKUP(D70,Data2023!$B$6:$F$24,5,0) -> 572.72727 | K70: =B74*IF(D70="PET 12",135,IF(D70="PA 15",135,120))*B80+318+B75 -> 798 | L70: =K70*(H70+G70)*F70 -> 2475214.2 | M70: =J70*(G70+H70)*F70 -> 1776469.5 | N70: =M70+L70 -> 4251683.7 | O70: =SUM(N70:N73) -> 20110785 | P70: =IF(P74=1,(IF(O70<$S$43,$U$43,IF(O70<$S$44,$U$44, IF(O70<$S$45,$U$45,IF(O70<$S$46,$U$46, IF(O70<$S$47,$U$47, IF(O70<$S$48,$U$48,IF(O70<$S$49,$U$49,IF(O70<$S$50,$U$50, IF(O70<$S$51,$U$51,0.07)))))))))),(IF(O70<$S$43,$W$43, IF(O70<$S$44,$W$44, IF(O70<$S$45,$W$45,IF(O70<$S$46,$W$46, IF(O70<$S$47,$W$47, IF(O70<$S$48,$W$48,IF(O70<$S$49,$W$49,IF(O70<$S$50,$W$50, IF(O70<$S$51,$W$51,0.14))))))))))) -> 0.14 | Q70: =O70+P72 -> 22926295 | S70: < | T70: 300000000 | U70: 0.07 | V70: =U70+3% -> 0.1 | W70: 0.17 | X70: 0.19
A71: Quai (0gr-7.2gr) | B71: 0 | C71: GHÉP LẦN 1 | D71: 0 | F71: =F70 -> 0.55 | G71: =IF(D71=0,0,G72+H72) -> 0 | H71: =IF(G71=0,0,G71/3000*20+100) -> 0 | J71: =VLOOKUP(D71,Data2023!$B$6:$F$24,5,0) -> 0 | K71: =IF(D71=0,0,684) -> 0 | L71: =K71*(H71+G71)*F71 -> 0 | M71: =J71*(G71+H71)*F71 -> 0 | N71: =M71+L71 -> 0 | S71: < | T71: 400000000 | U71: 0.06 | V71: =U71+3% -> 0.09 | W71: 0.16 | X71: 0.19
A72: Khổ trãi (m) | B72: 0.54 | C72: GHÉP LẦN 2 | D72: LLDPE | E72: 120 | F72: =F70 -> 0.55 | G72: =G73+H73 -> 4479 | H72: =G72/3000*20+100 -> 129.86 | I72: =VLOOKUP(D72,Data2023!$B$6:Data2023!$F$22,4,0) -> 40000 | J72: =VLOOKUP(D72,Data2023!$B$6:$F$24,5,0) -> 4440 | K72: =IF(D72=0,0,684) -> 684 | L72: =K72*(H72+G72)*F72 -> 1733853.1 | M72: =J72*(G72+H72)*F72 -> 11254836 | N72: =M72+L72 -> 12988689 | P72: =P70*O70 -> 2815509.9 | S72: < | T72: 600000000 | U72: 0.05 | V72: =U72+3% -> 0.08 | W72: 0.15 | X72: 0.18
A73: Bước cắt (m) | B73: 0.145 | C73: CPSX CẮT | E73: =IF(OR(D71=0,D72=0),3,6) -> 3 | F73: =F70 -> 0.55 | G73: =D68*B68 -> 4350 | H73: =G73/3000*20+100 -> 129 | J73: =VLOOKUP(D73,Data2023!$B$6:$F$24,5,0) -> 0 | K73: =IF(E68<0.07,971*1.4,IF(E68<0.2,971*1.2,971*0.8)) -> 1165.2 | L73: =K73*(H73+G73)*F73 -> 2870411.9 | M73: =(I79+J79)*D82 -> 0 | N73: =M73+L73 -> 2870411.9 | S73: > | T73: 600tr | U73: 0.04 | V73: =U73+3% -> 0.07 | W73: 0.11 | X73: =W73+3% -> 0.14
A74: Số màu in | B74: 4 | O74: lợi nhuận cột 1 hoặc 2 | P74: 2
A75: Màu nhũ/mờ =200 | B75: 0 | C75: HẠN MỤC | D75: ĐVT | E75: Giá | F75: Số lượng | G75: Thành tiền
A76: Zipper= 360/m | B76: 378 | C76: Truc in | D76: trục | E76: =IF(D68>=0.4,D68,IF(D68*2 >=0.4,D68*2,IF(D68*3 >=0.4,D68*3,IF(D68*4 >=0.4,D68*4,D68*5))))*IF(C68+0.1<0.7,0.7,C68+0.1)*7300000 -> 2222850 | F76: 1 | G76: =E76*F76 -> 2222850
A77: Tare (gr/cai) | B77: =(E68*B70)*0.93+B71 -> 9.6485175 | C77: Thùng giấy | D77: thùng | E77: 18000 | F77: =B68/1000 -> 30 | G77: =E77*F77 -> 540000
A78: Giá bán (chưa VAT) | B78: =P68 -> 808.0693 | C78: Vận chuyển | D78: tấn | E78: =IF(B71=0,1000000,1500000) -> 1000000 | F78: =B77*B68/1000000 -> 0.28945552 | G78: =F78*E78 -> 289455.53
A79: Thời gian sản xuất ( day) | B79: =B68/30000+4 -> 5 | C79: Lãi vay | D79: ngày | E79: =10%/365*100% -> 0.0002739726 | F79: 30 | G79: =F79*E79 -> 0.0082191781 | K79: in | L79: 1000000 | M79: 1000 | N79: 1000
A80: Tỉ lệ phủ mực in | B80: 1 | C80: Hoa hồng | D80: cái | E80: 0 | F80: =B68 -> 30000 | G80: =F80*E80*I68 -> 0 | K80: ghép | L80: 5000000 | M80: 5000 | N80: 1000
A81: Giá bán chốt | B81: =Q67
A82: kiểm tra tính giá | B82: =IF(SUM(E70:E73)=B70,"OK","SAI_Ô_F11") -> OK
O84: giá cty không hóa đơn | P84: =SUM(I89:N89)*1.05 -> 1665.4847
O85: giá hoa hồng khđ
O86: Giá chốt | P86: =P84+32 -> 1697.4847
A87: Khách hàng | C87: Khổ trãi | D87: Bước cắt | E87: Diện tích 1 túi m2 | F87: Tổng DT đơn hàng | G87: Khổ màng in thành phẩm | H87: Dài màng thành phẩm | I87: Giá vốn | J87: Truc in | K87: Zipper | L87: Thùng giấy | M87: Vận chuyển | N87: Lãi vay | O87: Hoa hồng | P87: Giá cuối | Q87: Giá bán chốt
A88: Tên hàng | B88: BEYONO CAO CAP | C88: m | D88: m | E88: m2 | F88: m2 | G88: m | H88: m | I88: túi | J88: =G97 -> 3842720 | K88: =(G94+H94)*B97 -> 2168712 | L88: =G98 -> 360000 | M88: =G99 -> 284356.8 | N88: =G100 -> 0.0082191781 | O88: =E101 -> 0 | P88: Chưa VAT | Q88: =P86 -> 1697.4847
A89: Số lượng TP | B89: 20000 | C89: =B93 -> 0.84 | D89: =B94 -> 0.28 | E89: =C89*D89 -> 0.2352 | F89: =B89*E89 -> 4704 | G89: =IF(C89>0.4,C89,C89*2) -> 0.84 | H89: =F89/G89 -> 5600 | I89: =Q91/B89 -> 1433.7383 | K89: =K88/B89 -> 108.4356 | L89: =L88/B89 -> 18 | M89: =G99/B89 -> 14.21784 | N89: =G100*I89 -> 11.784151 | O89: =O88*I89 -> 0 | P89: =SUM(I89:O89) -> 1586.1759 | Q89: =B102
A90: Cấu trúc | B90: PET//CPP | C90: HẠN MỤC CPSX | D90: MÀNG NL | E90: Độ dầy | F90: Khổ màng | G90: Số mét bán TP | H90: Phi hao | I90: Giá màng vnd/kg | J90: Thành tiền màng | K90: Chi phí sản xuất | L90: Thành tiền CPSX | M90: Giá màng In và ghép | N90: Giá vốn | O90: Tổng giá vốn | P90: LN | Q90: Doanh Thu
A91: Độ dầy (mic) | B91: 65 | C91: CPSX IN | D91: PET | E91: =VLOOKUP(D91, Data2023!$B$6:$F$23, 3, FALSE) -> 12 | F91: =IF(D91=0,0,F94+0.02) -> 0.86 | G91: =IF(D91=0,0,G94+H94+H93+H92) -> 5875.5822 | H91: =IF(B95=8,1800,IF(B95=7,1700,IF(B95=6,1500,IF(B95=5,1200,IF(B95=4,1000,IF(B95=3,800,IF(B95=2,500,400)))))))+(G91/6000*40)+IF(G91>50000,G91/50000*400,0) -> 539.17055 | I91: =VLOOKUP(D91,Data2023!$B$6:Data2023!$F$22,4,0) -> 34090.909 | J91: =VLOOKUP(D91,Data2023!$B$6:$F$24,5,0) -> 572.72727 | K91: =B95*IF(D91="PET 12",135,IF(D91="PA 15",135,120))*B101+318+B96 -> 958 | L91: =K91*(H91+G91)*F91 -> 5284986.5 | M91: =J91*(G91+H91)*F91 -> 3159557.3 | N91: =M91+L91 -> 8444543.8 | O91: =SUM(N91:N94) -> 25153304 | P91: =IF(P95=1,(IF(O91<$S$43,$U$43,IF(O91<$S$44,$U$44, IF(O91<$S$45,$U$45,IF(O91<$S$46,$U$46, IF(O91<$S$47,$U$47, IF(O91<$S$48,$U$48,IF(O91<$S$49,$U$49,IF(O91<$S$50,$U$50, IF(O91<$S$51,$U$51,0.07)))))))))),(IF(O91<$S$43,$W$43, IF(O91<$S$44,$W$44, IF(O91<$S$45,$W$45,IF(O91<$S$46,$W$46, IF(O91<$S$47,$W$47, IF(O91<$S$48,$W$48,IF(O91<$S$49,$W$49,IF(O91<$S$50,$W$50, IF(O91<$S$51,$W$51,0.14))))))))))) -> 0.14 | Q91: =O91+P93 -> 28674766
A92: Quai (0gr-7.2gr) | B92: 0 | C92: GHÉP LẦN 1 | D92: 0 | F92: =IF(D92=0,0,F94+0.02) -> 0 | G92: =IF(D92=0,0,G93+H93) -> 0 | H92: =IF(G92=0,0,G92/3000*20+100) -> 0 | J92: =VLOOKUP(D92,Data2023!$B$6:$F$24,5,0) -> 0 | K92: =IF(D92=0,0,684) -> 0 | L92: =K92*(H92+G92)*F92 -> 0 | M92: =J92*(G92+H92)*F92 -> 0 | N92: =M92+L92 -> 0
A93: Khổ trãi (m) | B93: =0.42*2 -> 0.84 | C93: GHÉP LẦN 2 | D93: CPP 50 | E93: =VLOOKUP(D93, Data2023!$B$6:$F$23, 3, FALSE) -> 50 | F93: =IF(D93=0,0,F94+0.02) -> 0.86 | G93: =IF(F93=0,0,H94+G94) -> 5737.3333 | H93: =IF(G93=0,0,(G93/3000*20+100)) -> 138.24889 | I93: =VLOOKUP(D93,Data2023!$B$6:Data2023!$F$22,4,0) -> 40909.091 | J93: =VLOOKUP(D93,Data2023!$B$6:$F$24,5,0) -> 1881.8182 | K93: =IF(D93=0,0,684) -> 684 | L93: =K93*(H93+G93)*F93 -> 3456252.5 | M93: =J93*(G93+H93)*F93 -> 9508828.6 | N93: =M93+L93 -> 12965081 | P93: =P91*O91 -> 3521462.5
A94: Bước cắt (m) | B94: 0.28 | C94: CPSX CẮT | E94: =IF(OR(D92=0,D93=0),3,6) -> 3 | F94: =G89 -> 0.84 | G94: =H89 -> 5600 | H94: =G94/3000*20+100 -> 137.33333 | J94: =VLOOKUP(D94,Data2023!$B$6:$F$24,5,0) -> 0 | K94: =IF(E89<0.07,971*1.4,IF(E89<0.2,971*1.2,971*0.8)) -> 776.8 | L94: =K94*(H94+G94)*F94 -> 3743678.8 | M94: =(I100+J100)*D103 -> 0 | N94: =M94+L94 -> 3743678.8
...

Sheet Giá màng 
A1: CTY CP LAI TRƯỜNG SƠN
A2: GIÁ MÀNG BOPP 18 mic in từ 1 đến 8 màu
A3: Báo giá có giá trị đến | C3: 44985
A4: Giá nầy áp dụng cho bộ trục đôi in 1 lần mặt trước và mặt sau
A5: TÊN MÀNG | B5: Giá bán | C5: Số màu in | D5: Nhủ | E5: Phủ mờ | F5: Khổ màng TP | G5: Màng in TP | H5: Màng in TP | I5: Khổ màng nguyên liệu | J5: Phi hao: in dư + phế | K5: Màng nguyên liệu | L5: CPMực + DM | M5: CPMực + DM | N5: Thời gian setup | O5: Thoi gian sx | P5: CPSX in + Chia | Q5: CPSX in + Chia | R5: Giá màng trắng | S5: CP màng trắng | T5: Tổng CPSX | U5: Giá vốn | V5: Lai vay | W5: Vận chuyển | X5: Lợi nhuận | Y5: Tỉ lệ mực in
B6: vnd/m2 | C6: Màu | D6: 200 | E6: 200 | F6: m | G6: m2 | H6: m | I6: m | J6: m | K6: m2 | L6: m2 | M6: vnd/set | N6: giờ | O6: giờ | P6: vnd/giờ | Q6: vnd/set | R6: vndm2 | S6: vnd/set | T6: vnd/set | U6: vnd/m2 | V6: 0.01 | W6: vnd/m2 | X6: 0 | Y6: %
A7: BOPP 18 mic | B7: =X7+W7+V7+U7 -> 4022.5444 | C7: 7 | D7: 0 | E7: 0 | F7: 1.02 | G7: =H7*F7 -> 3060 | H7: 3000 | I7: =F7+0.02 -> 1.04 | J7: =IF(C7=8,1900,IF(C7=7,1800,IF(C7=6,1400,IF(C7=5,1200,IF(C7=4,900,IF(C7=3,800,IF(C7=2,500,400)))))))+H7/6000*50+IF(H7>40000,H7/40000*400,0) -> 1825 | K7: =(J7+H7)*I7 -> 5018 | L7: =C7*IF(A7="BOPP 18 mic",110,160)*Y7+(E7+D7) -> 770 | M7: =L7*(H7+J7)*I7 -> 3863860 | N7: =C7*20/60 -> 2.3333333 | O7: =IF(H7>40000,H7/40000+H7/7500,H7/7500) -> 0.4 | P7: 1200000 | Q7: =P7*(O7+N7) -> 3280000 | R7: =VLOOKUP(A7,Data2023!B$6:F$23,5,0) -> 677.53636 | S7: =I7*(J7+H7)*R7 -> 3399877.5 | T7: =S7+Q7+M7 -> 10543737 | U7: =T7/G7 -> 3445.6658 | V7: =U7*V$6 -> 34.456658 | W7: =IF(G7<25000,500000,(G7/30000)*500000)/G7 -> 163.39869 | X7: =IF(C7<2,U7*17%,IF(C7<3,U7*16%,IF(C7<4,U7*15%,IF(C7<5,U7*14%,IF(C7<6,U7*13%,IF(C7<7,U7*12%,U7*11%)))))) -> 379.02324 | Y7: 1
A8: BOPP 18 mic | B8: =X8+W8+V8+U8 -> 3172.484 | C8: 7 | D8: 0 | E8: 0 | F8: 1.02 | G8: =H8*F8 -> 5100 | H8: 5000 | I8: =F8+0.02 -> 1.04 | J8: =IF(C8=8,1900,IF(C8=7,1800,IF(C8=6,1400,IF(C8=5,1200,IF(C8=4,900,IF(C8=3,800,IF(C8=2,500,400)))))))+H8/6000*50+IF(H8>40000,H8/40000*400,0) -> 1841.6667 | K8: =(J8+H8)*I8 -> 7115.3333 | L8: =C8*IF(A8="BOPP 18 mic",110,125)*Y8+(E8+D8) -> 770 | M8: =L8*(H8+J8)*I8 -> 5478806.7 | N8: =H8/60000+C8*20/60 -> 2.4166667 | O8: =IF(H8>40000,H8/40000+H8/7500,H8/7500) -> 0.66666667 | P8: 1200000 | Q8: =P8*(O8+N8) -> 3700000 | R8: =VLOOKUP(A8,Data2023!B$6:F$23,5,0) -> 677.53636 | S8: =I8*(J8+H8)*R8 -> 4820897.1 | T8: =S8+Q8+M8 -> 13999704 | U8: =T8/G8 -> 2745.0399 | V8: =U8*V$6 -> 27.450399 | W8: =IF(G8<25000,500000,(G8/30000)*500000)/G8 -> 98.039216 | X8: =IF(C8<2,U8*17%,IF(C8<3,U8*16%,IF(C8<4,U8*15%,IF(C8<5,U8*14%,IF(C8<6,U8*13%,IF(C8<7,U8*12%,U8*11%)))))) -> 301.95439 | Y8: 1
A9: BOPP 18 mic | B9: =X9+W9+V9+U9 -> 2660.0112 | C9: 7 | D9: 0 | E9: 0 | F9: 1.02 | G9: =H9*F9 -> 8160 | H9: =H8+3000 -> 8000 | I9: =F9+0.02 -> 1.04 | J9: =IF(C9=8,1900,IF(C9=7,1800,IF(C9=6,1400,IF(C9=5,1200,IF(C9=4,900,IF(C9=3,800,IF(C9=2,500,400)))))))+H9/6000*50+IF(H9>40000,H9/40000*400,0) -> 1866.6667 | K9: =(J9+H9)*I9 -> 10261.333 | L9: =C9*IF(A9="BOPP 18 mic",110,125)*Y9+(E9+D9) -> 770 | M9: =L9*(H9+J9)*I9 -> 7901226.7 | N9: =C9*20/60 -> 2.3333333 | O9: =IF(H9>40000,H9/40000+H9/7500,H9/7500) -> 1.0666667 | P9: 1200000 | Q9: =P9*(O9+N9) -> 4080000 | R9: =VLOOKUP(A9,Data2023!B$6:F$23,5,0) -> 677.53636 | S9: =I9*(J9+H9)*R9 -> 6952426.5 | T9: =S9+Q9+M9 -> 18933653 | U9: =T9/G9 -> 2320.3006 | V9: =U9*V$6 -> 23.203006 | W9: =IF(G9<25000,500000,(G9/30000)*500000)/G9 -> 61.27451 | X9: =IF(C9<2,U9*17%,IF(C9<3,U9*16%,IF(C9<4,U9*15%,IF(C9<5,U9*14%,IF(C9<6,U9*13%,IF(C9<7,U9*12%,U9*11%)))))) -> 255.23307 | Y9: 1
A10: BOPP 18 mic | B10: =X10+W10+V10+U10 -> 2437.0512 | C10: 7 | D10: 0 | E10: 0 | F10: 1.02 | G10: =H10*F10 -> 11220 | H10: =H9+3000 -> 11000 | I10: =F10+0.02 -> 1.04 | J10: =IF(C10=8,1900,IF(C10=7,1800,IF(C10=6,1400,IF(C10=5,1200,IF(C10=4,900,IF(C10=3,800,IF(C10=2,500,400)))))))+H10/6000*50+IF(H10>40000,H10/40000*400,0) -> 1891.6667 | K10: =(J10+H10)*I10 -> 13407.333 | L10: =C10*IF(A10="BOPP 18 mic",110,125)*Y10+(E10+D10) -> 770 | M10: =L10*(H10+J10)*I10 -> 10323647 | N10: =C10*20/60 -> 2.3333333 | O10: =IF(H10>40000,H10/40000+H10/7500,H10/7500) -> 1.4666667 | P10: 1200000 | Q10: =P10*(O10+N10) -> 4560000 | R10: =VLOOKUP(A10,Data2023!B$6:F$23,5,0) -> 677.53636 | S10: =I10*(J10+H10)*R10 -> 9083955.9 | T10: =S10+Q10+M10 -> 23967603 | U10: =T10/G10 -> 2136.15 | V10: =U10*V$6 -> 21.3615 | W10: =IF(G10<25000,500000,(G10/30000)*500000)/G10 -> 44.56328 | X10: =IF(C10<2,U10*17%,IF(C10<3,U10*16%,IF(C10<4,U10*15%,IF(C10<5,U10*14%,IF(C10<6,U10*13%,IF(C10<7,U10*12%,U10*11%)))))) -> 234.9765 | Y10: 1
A11: BOPP 18 mic | B11: =X11+W11+V11+U11 -> 2309.6455 | C11: 7 | D11: 0 | E11: 0 | F11: 1.02 | G11: =H11*F11 -> 14280 | H11: =H10+3000 -> 14000 | I11: =F11+0.02 -> 1.04 | J11: =IF(C11=8,1900,IF(C11=7,1800,IF(C11=6,1400,IF(C11=5,1200,IF(C11=4,900,IF(C11=3,800,IF(C11=2,500,400)))))))+H11/6000*50+IF(H11>40000,H11/40000*400,0) -> 1916.6667 | K11: =(J11+H11)*I11 -> 16553.333 | L11: =C11*IF(A11="BOPP 18 mic",110,125)*Y11+(E11+D11) -> 770 | M11: =L11*(H11+J11)*I11 -> 12746067 | N11: =C11*20/60 -> 2.3333333 | O11: =IF(H11>40000,H11/40000+H11/7500,H11/7500) -> 1.8666667 | P11: 1200000 | Q11: =P11*(O11+N11) -> 5040000 | R11: =VLOOKUP(A11,Data2023!B$6:F$23,5,0) -> 677.53636 | S11: =I11*(J11+H11)*R11 -> 11215485 | T11: =S11+Q11+M11 -> 29001552 | U11: =T11/G11 -> 2030.921 | V11: =U11*V$6 -> 20.30921 | W11: =IF(G11<25000,500000,(G11/30000)*500000)/G11 -> 35.014006 | X11: =IF(C11<2,U11*17%,IF(C11<3,U11*16%,IF(C11<4,U11*15%,IF(C11<5,U11*14%,IF(C11<6,U11*13%,IF(C11<7,U11*12%,U11*11%)))))) -> 223.40131 | Y11: 1
A12: BOPP 18 mic | B12: =X12+W12+V12+U12 -> 2227.2065 | C12: 7 | D12: 0 | E12: 0 | F12: 1.02 | G12: =H12*F12 -> 17340 | H12: =H11+3000 -> 17000 | I12: =F12+0.02 -> 1.04 | J12: =IF(C12=8,1900,IF(C12=7,1800,IF(C12=6,1400,IF(C12=5,1200,IF(C12=4,900,IF(C12=3,800,IF(C12=2,500,400)))))))+H12/6000*50+IF(H12>40000,H12/40000*400,0) -> 1941.6667 | K12: =(J12+H12)*I12 -> 19699.333 | L12: =C12*IF(A12="BOPP 18 mic",110,125)*Y12+(E12+D12) -> 770 | M12: =L12*(H12+J12)*I12 -> 15168487 | N12: =C12*20/60 -> 2.3333333 | O12: =IF(H12>40000,H12/40000+H12/7500,H12/7500) -> 2.2666667 | P12: 1200000 | Q12: =P12*(O12+N12) -> 5520000 | R12: =VLOOKUP(A12,Data2023!B$6:F$23,5,0) -> 677.53636 | S12: =I12*(J12+H12)*R12 -> 13347015 | T12: =S12+Q12+M12 -> 34035501 | U12: =T12/G12 -> 1962.8317 | V12: =U12*V$6 -> 19.628317 | W12: =IF(G12<25000,500000,(G12/30000)*500000)/G12 -> 28.835063 | X12: =IF(C12<2,U12*17%,IF(C12<3,U12*16%,IF(C12<4,U12*15%,IF(C12<5,U12*14%,IF(C12<6,U12*13%,IF(C12<7,U12*12%,U12*11%)))))) -> 215.91148 | Y12: 1
A13: BOPP 18 mic | B13: =X13+W13+V13+U13 -> 2169.4993 | C13: 7 | D13: 0 | E13: 0 | F13: 1.02 | G13: =H13*F13 -> 20400 | H13: =H12+3000 -> 20000 | I13: =F13+0.02 -> 1.04 | J13: =IF(C13=8,1900,IF(C13=7,1800,IF(C13=6,1400,IF(C13=5,1200,IF(C13=4,900,IF(C13=3,800,IF(C13=2,500,400)))))))+H13/6000*50+IF(H13>40000,H13/40000*400,0) -> 1966.6667 | K13: =(J13+H13)*I13 -> 22845.333 | L13: =C13*IF(A13="BOPP 18 mic",110,125)*Y13+(E13+D13) -> 770 | M13: =L13*(H13+J13)*I13 -> 17590907 | N13: =C13*20/60 -> 2.3333333 | O13: =IF(H13>40000,H13/40000+H13/7500,H13/7500) -> 2.6666667 | P13: 1200000 | Q13: =P13*(O13+N13) -> 6000000 | R13: =VLOOKUP(A13,Data2023!B$6:F$23,5,0) -> 677.53636 | S13: =I13*(J13+H13)*R13 -> 15478544 | T13: =S13+Q13+M13 -> 39069451 | U13: =T13/G13 -> 1915.1692 | V13: =U13*V$6 -> 19.151692 | W13: =IF(G13<25000,500000,(G13/30000)*500000)/G13 -> 24.509804 | X13: =IF(C13<2,U13*17%,IF(C13<3,U13*16%,IF(C13<4,U13*15%,IF(C13<5,U13*14%,IF(C13<6,U13*13%,IF(C13<7,U13*12%,U13*11%)))))) -> 210.66861 | Y13: 1
A14: BOPP 18 mic | B14: =X14+W14+V14+U14 -> 2101.1565 | C14: 7 | D14: 0 | E14: 0 | F14: 1.02 | G14: =H14*F14 -> 25500 | H14: =H13+5000 -> 25000 | I14: =F14+0.02 -> 1.04 | J14: =IF(C14=8,1900,IF(C14=7,1800,IF(C14=6,1400,IF(C14=5,1200,IF(C14=4,900,IF(C14=3,800,IF(C14=2,500,400)))))))+H14/6000*50+IF(H14>40000,H14/40000*400,0) -> 2008.3333 | K14: =(J14+H14)*I14 -> 28088.667 | L14: =C14*IF(A14="BOPP 18 mic",110,125)*Y14+(E14+D14) -> 770 | M14: =L14*(H14+J14)*I14 -> 21628273 | N14: =C14*20/60 -> 2.3333333 | O14: =IF(H14>40000,H14/40000+H14/7500,H14/7500) -> 3.3333333 | P14: 1200000 | Q14: =P14*(O14+N14) -> 6800000 | R14: =VLOOKUP(A14,Data2023!B$6:F$23,5,0) -> 677.53636 | S14: =I14*(J14+H14)*R14 -> 19031093 | T14: =S14+Q14+M14 -> 47459366 | U14: =T14/G14 -> 1861.1516 | V14: =U14*V$6 -> 18.611516 | W14: =IF(G14<25000,500000,(G14/30000)*500000)/G14 -> 16.666667 | X14: =IF(C14<2,U14*17%,IF(C14<3,U14*16%,IF(C14<4,U14*15%,IF(C14<5,U14*14%,IF(C14<6,U14*13%,IF(C14<7,U14*12%,U14*11%)))))) -> 204.72668 | Y14: 1
A15: BOPP 18 mic | B15: =X15+W15+V15+U15 -> 2060.8234 | C15: 7 | D15: 0 | E15: 0 | F15: 1.02 | G15: =H15*F15 -> 30600 | H15: =H14+5000 -> 30000 | I15: =F15+0.02 -> 1.04 | J15: =IF(C15=8,1900,IF(C15=7,1800,IF(C15=6,1400,IF(C15=5,1200,IF(C15=4,900,IF(C15=3,800,IF(C15=2,500,400)))))))+H15/6000*50+IF(H15>40000,H15/40000*400,0) -> 2050 | K15: =(J15+H15)*I15 -> 33332 | L15: =C15*IF(A15="BOPP 18 mic",110,125)*Y15+(E15+D15) -> 770 | M15: =L15*(H15+J15)*I15 -> 25665640 | N15: =C15*20/60 -> 2.3333333 | O15: =IF(H15>40000,H15/40000+H15/7500,H15/7500) -> 4 | P15: 1200000 | Q15: =P15*(O15+N15) -> 7600000 | R15: =VLOOKUP(A15,Data2023!B$6:F$23,5,0) -> 677.53636 | S15: =I15*(J15+H15)*R15 -> 22583642 | T15: =S15+Q15+M15 -> 55849282 | U15: =T15/G15 -> 1825.1399 | V15: =U15*V$6 -> 18.251399 | W15: =IF(G15<25000,500000,(G15/30000)*500000)/G15 -> 16.666667 | X15: =IF(C15<2,U15*17%,IF(C15<3,U15*16%,IF(C15<4,U15*15%,IF(C15<5,U15*14%,IF(C15<6,U15*13%,IF(C15<7,U15*12%,U15*11%)))))) -> 200.76539 | Y15: 1
A16: BOPP 18 mic | B16: =X16+W16+V16+U16 -> 2032.014 | C16: 7 | D16: 0 | E16: 0 | F16: 1.02 | G16: =H16*F16 -> 35700 | H16: =H15+5000 -> 35000 | I16: =F16+0.02 -> 1.04 | J16: =IF(C16=8,1900,IF(C16=7,1800,IF(C16=6,1400,IF(C16=5,1200,IF(C16=4,900,IF(C16=3,800,IF(C16=2,500,400)))))))+H16/6000*50+IF(H16>40000,H16/40000*400,0) -> 2091.6667 | K16: =(J16+H16)*I16 -> 38575.333 | L16: =C16*IF(A16="BOPP 18 mic",110,125)*Y16+(E16+D16) -> 770 | M16: =L16*(H16+J16)*I16 -> 29703007 | N16: =C16*20/60 -> 2.3333333 | O16: =IF(H16>40000,H16/40000+H16/7500,H16/7500) -> 4.6666667 | P16: 1200000 | Q16: =P16*(O16+N16) -> 8400000 | R16: =VLOOKUP(A16,Data2023!B$6:F$23,5,0) -> 677.53636 | S16: =I16*(J16+H16)*R16 -> 26136191 | T16: =S16+Q16+M16 -> 64239198 | U16: =T16/G16 -> 1799.4173 | V16: =U16*V$6 -> 17.994173 | W16: =IF(G16<25000,500000,(G16/30000)*500000)/G16 -> 16.666667 | X16: =IF(C16<2,U16*17%,IF(C16<3,U16*16%,IF(C16<4,U16*15%,IF(C16<5,U16*14%,IF(C16<6,U16*13%,IF(C16<7,U16*12%,U16*11%)))))) -> 197.9359 | Y16: 1
A17: BOPP 18 mic | B17: =X17+W17+V17+U17 -> 2010.407 | C17: 7 | D17: 0 | E17: 0 | F17: 1.02 | G17: =H17*F17 -> 40800 | H17: =H16+5000 -> 40000 | I17: =F17+0.02 -> 1.04 | J17: =IF(C17=8,1900,IF(C17=7,1800,IF(C17=6,1400,IF(C17=5,1200,IF(C17=4,900,IF(C17=3,800,IF(C17=2,500,400)))))))+H17/6000*50+IF(H17>40000,H17/40000*400,0) -> 2133.3333 | K17: =(J17+H17)*I17 -> 43818.667 | L17: =C17*IF(A17="BOPP 18 mic",110,125)*Y17+(E17+D17) -> 770 | M17: =L17*(H17+J17)*I17 -> 33740373 | N17: =C17*20/60 -> 2.3333333 | O17: =IF(H17>40000,H17/40000+H17/7500,H17/7500) -> 5.3333333 | P17: 1200000 | Q17: =P17*(O17+N17) -> 9200000 | R17: =VLOOKUP(A17,Data2023!B$6:F$23,5,0) -> 677.53636 | S17: =I17*(J17+H17)*R17 -> 29688740 | T17: =S17+Q17+M17 -> 72629113 | U17: =T17/G17 -> 1780.1253 | V17: =U17*V$6 -> 17.801253 | W17: =IF(G17<25000,500000,(G17/30000)*500000)/G17 -> 16.666667 | X17: =IF(C17<2,U17*17%,IF(C17<3,U17*16%,IF(C17<4,U17*15%,IF(C17<5,U17*14%,IF(C17<6,U17*13%,IF(C17<7,U17*12%,U17*11%)))))) -> 195.81379 | Y17: 1
A18: BOPP 18 mic | B18: =X18+W18+V18+U18 -> 2043.0731 | C18: 7 | D18: 0 | E18: 0 | F18: 1.02 | G18: =H18*F18 -> 45900 | H18: =H17+5000 -> 45000 | I18: =F18+0.02 -> 1.04 | J18: =IF(C18=8,1900,IF(C18=7,1800,IF(C18=6,1400,IF(C18=5,1200,IF(C18=4,900,IF(C18=3,800,IF(C18=2,500,400)))))))+H18/6000*50+IF(H18>40000,H18/40000*400,0) -> 2625 | K18: =(J18+H18)*I18 -> 49530 | L18: =C18*IF(A18="BOPP 18 mic",110,125)*Y18+(E18+D18) -> 770 | M18: =L18*(H18+J18)*I18 -> 38138100 | N18: =C18*20/60 -> 2.3333333 | O18: =IF(H18>40000,H18/40000+H18/7500,H18/7500) -> 7.125 | P18: 1200000 | Q18: =P18*(O18+N18) -> 11350000 | R18: =VLOOKUP(A18,Data2023!B$6:F$23,5,0) -> 677.53636 | S18: =I18*(J18+H18)*R18 -> 33558376 | T18: =S18+Q18+M18 -> 83046476 | U18: =T18/G18 -> 1809.2914 | V18: =U18*V$6 -> 18.092914 | W18: =IF(G18<25000,500000,(G18/30000)*500000)/G18 -> 16.666667 | X18: =IF(C18<2,U18*17%,IF(C18<3,U18*16%,IF(C18<4,U18*15%,IF(C18<5,U18*14%,IF(C18<6,U18*13%,IF(C18<7,U18*12%,U18*11%)))))) -> 199.02206 | Y18: 1
A19: BOPP 18 mic | B19: =X19+W19+V19+U19 -> 2029.6287 | C19: 7 | D19: 0 | E19: 0 | F19: 1.02 | G19: =H19*F19 -> 51000 | H19: =H18+5000 -> 50000 | I19: =F19+0.02 -> 1.04 | J19: =IF(C19=8,1900,IF(C19=7,1800,IF(C19=6,1400,IF(C19=5,1200,IF(C19=4,900,IF(C19=3,800,IF(C19=2,500,400)))))))+H19/6000*50+IF(H19>40000,H19/40000*400,0) -> 2716.6667 | K19: =(J19+H19)*I19 -> 54825.333 | L19: =C19*IF(A19="BOPP 18 mic",110,125)*Y19+(E19+D19) -> 770 | M19: =L19*(H19+J19)*I19 -> 42215507 | N19: =C19*20/60 -> 2.3333333 | O19: =IF(H19>40000,H19/40000+H19/7500,H19/7500) -> 7.9166667 | P19: 1200000 | Q19: =P19*(O19+N19) -> 12300000 | R19: =VLOOKUP(A19,Data2023!B$6:F$23,5,0) -> 677.53636 | S19: =I19*(J19+H19)*R19 -> 37146157 | T19: =S19+Q19+M19 -> 91661664 | U19: =T19/G19 -> 1797.2875 | V19: =U19*V$6 -> 17.972875 | W19: =IF(G19<25000,500000,(G19/30000)*500000)/G19 -> 16.666667 | X19: =IF(C19<2,U19*17%,IF(C19<3,U19*16%,IF(C19<4,U19*15%,IF(C19<5,U19*14%,IF(C19<6,U19*13%,IF(C19<7,U19*12%,U19*11%)))))) -> 197.70163 | Y19: 1
A20: BOPP 18 mic | B20: =X20+W20+V20+U20 -> 2018.6288 | C20: 7 | D20: 0 | E20: 0 | F20: 1.02 | G20: =H20*F20 -> 56100 | H20: =H19+5000 -> 55000 | I20: =F20+0.02 -> 1.04 | J20: =IF(C20=8,1900,IF(C20=7,1800,IF(C20=6,1400,IF(C20=5,1200,IF(C20=4,900,IF(C20=3,800,IF(C20=2,500,400)))))))+H20/6000*50+IF(H20>40000,H20/40000*400,0) -> 2808.3333 | K20: =(J20+H20)*I20 -> 60120.667 | L20: =C20*IF(A20="BOPP 18 mic",110,125)*Y20+(E20+D20) -> 770 | M20: =L20*(H20+J20)*I20 -> 46292913 | N20: =C20*20/60 -> 2.3333333 | O20: =IF(H20>40000,H20/40000+H20/7500,H20/7500) -> 8.7083333 | P20: 1200000 | Q20: =P20*(O20+N20) -> 13250000 | R20: =VLOOKUP(A20,Data2023!B$6:F$23,5,0) -> 677.53636 | S20: =I20*(J20+H20)*R20 -> 40733938 | T20: =S20+Q20+M20 -> 1.0027685e+08 | U20: =T20/G20 -> 1787.4662 | V20: =U20*V$6 -> 17.874662 | W20: =IF(G20<25000,500000,(G20/30000)*500000)/G20 -> 16.666667 | X20: =IF(C20<2,U20*17%,IF(C20<3,U20*16%,IF(C20<4,U20*15%,IF(C20<5,U20*14%,IF(C20<6,U20*13%,IF(C20<7,U20*12%,U20*11%)))))) -> 196.62128 | Y20: 1
A21: BOPP 18 mic | B21: =X21+W21+V21+U21 -> 2009.4621 | C21: 7 | D21: 0 | E21: 0 | F21: 1.02 | G21: =H21*F21 -> 61200 | H21: =H20+5000 -> 60000 | I21: =F21+0.02 -> 1.04 | J21: =IF(C21=8,1900,IF(C21=7,1800,IF(C21=6,1400,IF(C21=5,1200,IF(C21=4,900,IF(C21=3,800,IF(C21=2,500,400)))))))+H21/6000*50+IF(H21>40000,H21/40000*400,0) -> 2900 | K21: =(J21+H21)*I21 -> 65416 | L21: =C21*IF(A21="BOPP 18 mic",110,125)*Y21+(E21+D21) -> 770 | M21: =L21*(H21+J21)*I21 -> 50370320 | N21: =C21*20/60 -> 2.3333333 | O21: =IF(H21>40000,H21/40000+H21/7500,H21/7500) -> 9.5 | P21: 1200000 | Q21: =P21*(O21+N21) -> 14200000 | R21: =VLOOKUP(A21,Data2023!B$6:F$23,5,0) -> 677.53636 | S21: =I21*(J21+H21)*R21 -> 44321719 | T21: =S21+Q21+M21 -> 1.0889204e+08 | U21: =T21/G21 -> 1779.2817 | V21: =U21*V$6 -> 17.792817 | W21: =IF(G21<25000,500000,(G21/30000)*500000)/G21 -> 16.666667 | X21: =IF(C21<2,U21*17%,IF(C21<3,U21*16%,IF(C21<4,U21*15%,IF(C21<5,U21*14%,IF(C21<6,U21*13%,IF(C21<7,U21*12%,U21*11%)))))) -> 195.72098 | Y21: 1
A22: BOPP 18 mic | B22: =X22+W22+V22+U22 -> 2001.7058 | C22: 7 | D22: 0 | E22: 0 | F22: 1.02 | G22: =H22*F22 -> 66300 | H22: =H21+5000 -> 65000 | I22: =F22+0.02 -> 1.04 | J22: =IF(C22=8,1900,IF(C22=7,1800,IF(C22=6,1400,IF(C22=5,1200,IF(C22=4,900,IF(C22=3,800,IF(C22=2,500,400)))))))+H22/6000*50+IF(H22>40000,H22/40000*400,0) -> 2991.6667 | K22: =(J22+H22)*I22 -> 70711.333 | L22: =C22*IF(A22="BOPP 18 mic",110,125)*Y22+(E22+D22) -> 770 | M22: =L22*(H22+J22)*I22 -> 54447727 | N22: =C22*20/60 -> 2.3333333 | O22: =IF(H22>40000,H22/40000+H22/7500,H22/7500) -> 10.291667 | P22: 1200000 | Q22: =P22*(O22+N22) -> 15150000 | R22: =VLOOKUP(A22,Data2023!B$6:F$23,5,0) -> 677.53636 | S22: =I22*(J22+H22)*R22 -> 47909500 | T22: =S22+Q22+M22 -> 1.1750723e+08 | U22: =T22/G22 -> 1772.3564 | V22: =U22*V$6 -> 17.723564 | W22: =IF(G22<25000,500000,(G22/30000)*500000)/G22 -> 16.666667 | X22: =IF(C22<2,U22*17%,IF(C22<3,U22*16%,IF(C22<4,U22*15%,IF(C22<5,U22*14%,IF(C22<6,U22*13%,IF(C22<7,U22*12%,U22*11%)))))) -> 194.9592 | Y22: 1
A23: BOPP 18 mic | B23: =X23+W23+V23+U23 -> 1995.0575 | C23: 7 | D23: 0 | E23: 0 | F23: 1.02 | G23: =H23*F23 -> 71400 | H23: =H22+5000 -> 70000 | I23: =F23+0.02 -> 1.04 | J23: =IF(C23=8,1900,IF(C23=7,1800,IF(C23=6,1400,IF(C23=5,1200,IF(C23=4,900,IF(C23=3,800,IF(C23=2,500,400)))))))+H23/6000*50+IF(H23>40000,H23/40000*400,0) -> 3083.3333 | K23: =(J23+H23)*I23 -> 76006.667 | L23: =C23*IF(A23="BOPP 18 mic",110,125)*Y23+(E23+D23) -> 770 | M23: =L23*(H23+J23)*I23 -> 58525133 | N23: =C23*20/60 -> 2.3333333 | O23: =IF(H23>40000,H23/40000+H23/7500,H23/7500) -> 11.083333 | P23: 1200000 | Q23: =P23*(O23+N23) -> 16100000 | R23: =VLOOKUP(A23,Data2023!B$6:F$23,5,0) -> 677.53636 | S23: =I23*(J23+H23)*R23 -> 51497281 | T23: =S23+Q23+M23 -> 1.2612241e+08 | U23: =T23/G23 -> 1766.4204 | V23: =U23*V$6 -> 17.664204 | W23: =IF(G23<25000,500000,(G23/30000)*500000)/G23 -> 16.666667 | X23: =IF(C23<2,U23*17%,IF(C23<3,U23*16%,IF(C23<4,U23*15%,IF(C23<5,U23*14%,IF(C23<6,U23*13%,IF(C23<7,U23*12%,U23*11%)))))) -> 194.30624 | Y23: 1
A24: BOPP 18 mic | B24: =X24+W24+V24+U24 -> 1989.2956 | C24: 7 | D24: 0 | E24: 0 | F24: 1.02 | G24: =H24*F24 -> 76500 | H24: =H23+5000 -> 75000 | I24: =F24+0.02 -> 1.04 | J24: =IF(C24=8,1900,IF(C24=7,1800,IF(C24=6,1400,IF(C24=5,1200,IF(C24=4,900,IF(C24=3,800,IF(C24=2,500,400)))))))+H24/6000*50+IF(H24>40000,H24/40000*400,0) -> 3175 | K24: =(J24+H24)*I24 -> 81302 | L24: =C24*IF(A24="BOPP 18 mic",110,125)*Y24+(E24+D24) -> 770 | M24: =L24*(H24+J24)*I24 -> 62602540 | N24: =C24*20/60 -> 2.3333333 | O24: =IF(H24>40000,H24/40000+H24/7500,H24/7500) -> 11.875 | P24: 1200000 | Q24: =P24*(O24+N24) -> 17050000 | R24: =VLOOKUP(A24,Data2023!B$6:F$23,5,0) -> 677.53636 | S24: =I24*(J24+H24)*R24 -> 55085061 | T24: =S24+Q24+M24 -> 1.347376e+08 | U24: =T24/G24 -> 1761.2758 | V24: =U24*V$6 -> 17.612758 | W24: =IF(G24<25000,500000,(G24/30000)*500000)/G24 -> 16.666667 | X24: =IF(C24<2,U24*17%,IF(C24<3,U24*16%,IF(C24<4,U24*15%,IF(C24<5,U24*14%,IF(C24<6,U24*13%,IF(C24<7,U24*12%,U24*11%)))))) -> 193.74034 | Y24: 1
A25: BOPP 18 mic | B25: =X25+W25+V25+U25 -> 1984.254 | C25: 7 | D25: 0 | E25: 0 | F25: 1.02 | G25: =H25*F25 -> 81600 | H25: =H24+5000 -> 80000 | I25: =F25+0.02 -> 1.04 | J25: =IF(C25=8,1900,IF(C25=7,1800,IF(C25=6,1400,IF(C25=5,1200,IF(C25=4,900,IF(C25=3,800,IF(C25=2,500,400)))))))+H25/6000*50+IF(H25>40000,H25/40000*400,0) -> 3266.6667 | K25: =(J25+H25)*I25 -> 86597.333 | L25: =C25*IF(A25="BOPP 18 mic",110,125)*Y25+(E25+D25) -> 770 | M25: =L25*(H25+J25)*I25 -> 66679947 | N25: =C25*20/60 -> 2.3333333 | O25: =IF(H25>40000,H25/40000+H25/7500,H25/7500) -> 12.666667 | P25: 1200000 | Q25: =P25*(O25+N25) -> 18000000 | R25: =VLOOKUP(A25,Data2023!B$6:F$23,5,0) -> 677.53636 | S25: =I25*(J25+H25)*R25 -> 58672842 | T25: =S25+Q25+M25 -> 143352789 | U25: =T25/G25 -> 1756.7744 | V25: =U25*V$6 -> 17.567744 | W25: =IF(G25<25000,500000,(G25/30000)*500000)/G25 -> 16.666667 | X25: =IF(C25<2,U25*17%,IF(C25<3,U25*16%,IF(C25<4,U25*15%,IF(C25<5,U25*14%,IF(C25<6,U25*13%,IF(C25<7,U25*12%,U25*11%)))))) -> 193.24518 | Y25: 1
... A59: BOPP 18 mic | B59: =X59+W59+V59+U59 -> 1932.8293 | C59: 7 | D59: 0 | E59: 0 | F59: 1.02 | G59: =H59*F59 -> 255000 | H59: =H58+5000 -> 250000 | I59: =F59+0.02 -> 1.04 | J59: =IF(C59=8,1900,IF(C59=7,1800,IF(C59=6,1400,IF(C59=5,1200,IF(C59=4,900,IF(C59=3,800,IF(C59=2,500,400)))))))+H59/6000*50+IF(H59>40000,H59/40000*400,0) -> 6383.3333 | K59: =(J59+H59)*I59 -> 266638.67 | L59: =C59*IF(A59="BOPP 18 mic",110,125)*Y59+(E59+D59) -> 770 | M59: =L59*(H59+J59)*I59 -> 2.0531177e+08 | N59: =C59*20/60 -> 2.3333333 | O59: =IF(H59>40000,H59/40000+H59/7500,H59/7500) -> 39.583333 | P59: 1200000 | Q59: =P59*(O59+N59) -> 50300000 | R59: =VLOOKUP(A59,Data2023!B$6:F$23,5,0) -> 677.53636 | S59: =I59*(J59+H59)*R59 -> 1.8065739e+08 | T59: =S59+Q59+M59 -> 436269166 | U59: =T59/G59 -> 1710.8595 | V59: =U59*V$6 -> 17.108595 | W59: =IF(G59<25000,500000,(G59/30000)*500000)/G59 -> 16.666667 | X59: =IF(C59<2,U59*17%,IF(C59<3,U59*16%,IF(C59<4,U59*15%,IF(C59<5,U59*14%,IF(C59<6,U59*13%,IF(C59<7,U59*12%,U59*11%)))))) -> 188.19454 | Y59: 1
A60: BOPP 18 mic | B60: =X60+W60+V60+U60 -> 1932.3548 | C60: 7 | D60: 0 | E60: 0 | F60: 1.02 | G60: =H60*F60 -> 260100 | H60: 255000 | I60: =F60+0.02 -> 1.04 | J60: =IF(C60=8,1900,IF(C60=7,1800,IF(C60=6,1400,IF(C60=5,1200,IF(C60=4,900,IF(C60=3,800,IF(C60=2,500,400)))))))+H60/6000*50+IF(H60>40000,H60/40000*400,0) -> 6475 | K60: =(J60+H60)*I60 -> 271934 | L60: =C60*IF(A60="BOPP 18 mic",110,125)*Y60+(E60+D60) -> 770 | M60: =L60*(H60+J60)*I60 -> 209389180 | N60: =C60*20/60 -> 2.3333333 | O60: =IF(H60>40000,H60/40000+H60/7500,H60/7500) -> 40.375 | P60: 1200000 | Q60: =P60*(O60+N60) -> 51250000 | R60: =VLOOKUP(A60,Data2023!B$6:F$23,5,0) -> 677.53636 | S60: =I60*(J60+H60)*R60 -> 1.8424517e+08 | T60: =S60+Q60+M60 -> 4.4488435e+08 | U60: =T60/G60 -> 1710.4358 | V60: =U60*V$6 -> 17.104358 | W60: =IF(G60<25000,500000,(G60/30000)*500000)/G60 -> 16.666667 | X60: =IF(C60<2,U60*17%,IF(C60<3,U60*16%,IF(C60<4,U60*15%,IF(C60<5,U60*14%,IF(C60<6,U60*13%,IF(C60<7,U60*12%,U60*11%)))))) -> 188.14794 | Y60: 1
A61: BOPP 18 mic | B61: =X61+W61+V61+U61 -> 1931.8985 | C61: 7 | D61: 0 | E61: 0 | F61: 1.02 | G61: =H61*F61 -> 265200 | H61: =H60+5000 -> 260000 | I61: =F61+0.02 -> 1.04 | J61: =IF(C61=8,1900,IF(C61=7,1800,IF(C61=6,1400,IF(C61=5,1200,IF(C61=4,900,IF(C61=3,800,IF(C61=2,500,400)))))))+H61/6000*50+IF(H61>40000,H61/40000*400,0) -> 6566.6667 | K61: =(J61+H61)*I61 -> 277229.33 | L61: =C61*IF(A61="BOPP 18 mic",110,125)*Y61+(E61+D61) -> 770 | M61: =L61*(H61+J61)*I61 -> 2.1346659e+08 | N61: =C61*20/60 -> 2.3333333 | O61: =IF(H61>40000,H61/40000+H61/7500,H61/7500) -> 41.166667 | P61: 1200000 | Q61: =P61*(O61+N61) -> 52200000 | R61: =VLOOKUP(A61,Data2023!B$6:F$23,5,0) -> 677.53636 | S61: =I61*(J61+H61)*R61 -> 1.8783295e+08 | T61: =S61+Q61+M61 -> 4.5349954e+08 | U61: =T61/G61 -> 1710.0284 | V61: =U61*V$6 -> 17.100284 | W61: =IF(G61<25000,500000,(G61/30000)*500000)/G61 -> 16.666667 | X61: =IF(C61<2,U61*17%,IF(C61<3,U61*16%,IF(C61<4,U61*15%,IF(C61<5,U61*14%,IF(C61<6,U61*13%,IF(C61<7,U61*12%,U61*11%)))))) -> 188.10313 | Y61: 1
A62: BOPP 18 mic | B62: =X62+W62+V62+U62 -> 1931.4595 | C62: 7 | D62: 0 | E62: 0 | F62: 1.02 | G62: =H62*F62 -> 270300 | H62: =H61+5000 -> 265000 | I62: =F62+0.02 -> 1.04 | J62: =IF(C62=8,1900,IF(C62=7,1800,IF(C62=6,1400,IF(C62=5,1200,IF(C62=4,900,IF(C62=3,800,IF(C62=2,500,400)))))))+H62/6000*50+IF(H62>40000,H62/40000*400,0) -> 6658.3333 | K62: =(J62+H62)*I62 -> 282524.67 | L62: =C62*IF(A62="BOPP 18 mic",110,125)*Y62+(E62+D62) -> 770 | M62: =L62*(H62+J62)*I62 -> 2.1754399e+08 | N62: =C62*20/60 -> 2.3333333 | O62: =IF(H62>40000,H62/40000+H62/7500,H62/7500) -> 41.958333 | P62: 1200000 | Q62: =P62*(O62+N62) -> 53150000 | R62: =VLOOKUP(A62,Data2023!B$6:F$23,5,0) -> 677.53636 | S62: =I62*(J62+H62)*R62 -> 1.9142074e+08 | T62: =S62+Q62+M62 -> 4.6211473e+08 | U62: =T62/G62 -> 1709.6364 | V62: =U62*V$6 -> 17.096364 | W62: =IF(G62<25000,500000,(G62/30000)*500000)/G62 -> 16.666667 | X62: =IF(C62<2,U62*17%,IF(C62<3,U62*16%,IF(C62<4,U62*15%,IF(C62<5,U62*14%,IF(C62<6,U62*13%,IF(C62<7,U62*12%,U62*11%)))))) -> 188.06001 | Y62: 1
A63: BOPP 18 mic | B63: =X63+W63+V63+U63 -> 1931.0367 | C63: 7 | D63: 0 | E63: 0 | F63: 1.02 | G63: =H63*F63 -> 275400 | H63: =H62+5000 -> 270000 | I63: =F63+0.02 -> 1.04 | J63: =IF(C63=8,1900,IF(C63=7,1800,IF(C63=6,1400,IF(C63=5,1200,IF(C63=4,900,IF(C63=3,800,IF(C63=2,500,400)))))))+H63/6000*50+IF(H63>40000,H63/40000*400,0) -> 6750 | K63: =(J63+H63)*I63 -> 287820 | L63: =C63*IF(A63="BOPP 18 mic",110,125)*Y63+(E63+D63) -> 770 | M63: =L63*(H63+J63)*I63 -> 221621400 | N63: =C63*20/60 -> 2.3333333 | O63: =IF(H63>40000,H63/40000+H63/7500,H63/7500) -> 42.75 | P63: 1200000 | Q63: =P63*(O63+N63) -> 54100000 | R63: =VLOOKUP(A63,Data2023!B$6:F$23,5,0) -> 677.53636 | S63: =I63*(J63+H63)*R63 -> 1.9500852e+08 | T63: =S63+Q63+M63 -> 4.7072992e+08 | U63: =T63/G63 -> 1709.259 | V63: =U63*V$6 -> 17.09259 | W63: =IF(G63<25000,500000,(G63/30000)*500000)/G63 -> 16.666667 | X63: =IF(C63<2,U63*17%,IF(C63<3,U63*16%,IF(C63<4,U63*15%,IF(C63<5,U63*14%,IF(C63<6,U63*13%,IF(C63<7,U63*12%,U63*11%)))))) -> 188.01848 | Y63: 1
A64: BOPP 18 mic | B64: =X64+W64+V64+U64 -> 1930.6293 | C64: 7 | D64: 0 | E64: 0 | F64: 1.02 | G64: =H64*F64 -> 280500 | H64: =H63+5000 -> 275000 | I64: =F64+0.02 -> 1.04 | J64: =IF(C64=8,1900,IF(C64=7,1800,IF(C64=6,1400,IF(C64=5,1200,IF(C64=4,900,IF(C64=3,800,IF(C64=2,500,400)))))))+H64/6000*50+IF(H64>40000,H64/40000*400,0) -> 6841.6667 | K64: =(J64+H64)*I64 -> 293115.33 | L64: =C64*IF(A64="BOPP 18 mic",110,125)*Y64+(E64+D64) -> 770 | M64: =L64*(H64+J64)*I64 -> 2.2569881e+08 | N64: =C64*20/60 -> 2.3333333 | O64: =IF(H64>40000,H64/40000+H64/7500,H64/7500) -> 43.541667 | P64: 1200000 | Q64: =P64*(O64+N64) -> 55050000 | R64: =VLOOKUP(A64,Data2023!B$6:F$23,5,0) -> 677.53636 | S64: =I64*(J64+H64)*R64 -> 1.985963e+08 | T64: =S64+Q64+M64 -> 4.793451e+08 | U64: =T64/G64 -> 1708.8952 | V64: =U64*V$6 -> 17.088952 | W64: =IF(G64<25000,500000,(G64/30000)*500000)/G64 -> 16.666667 | X64: =IF(C64<2,U64*17%,IF(C64<3,U64*16%,IF(C64<4,U64*15%,IF(C64<5,U64*14%,IF(C64<6,U64*13%,IF(C64<7,U64*12%,U64*11%)))))) -> 187.97847 | Y64: 1
A65: BOPP 18 mic | B65: =X65+W65+V65+U65 -> 1930.2364 | C65: 7 | D65: 0 | E65: 0 | F65: 1.02 | G65: =H65*F65 -> 285600 | H65: =H64+5000 -> 280000 | I65: =F65+0.02 -> 1.04 | J65: =IF(C65=8,1900,IF(C65=7,1800,IF(C65=6,1400,IF(C65=5,1200,IF(C65=4,900,IF(C65=3,800,IF(C65=2,500,400)))))))+H65/6000*50+IF(H65>40000,H65/40000*400,0) -> 6933.3333 | K65: =(J65+H65)*I65 -> 298410.67 | L65: =C65*IF(A65="BOPP 18 mic",110,125)*Y65+(E65+D65) -> 770 | M65: =L65*(H65+J65)*I65 -> 2.2977621e+08 | N65: =C65*20/60 -> 2.3333333 | O65: =IF(H65>40000,H65/40000+H65/7500,H65/7500) -> 44.333333 | P65: 1200000 | Q65: =P65*(O65+N65) -> 56000000 | R65: =VLOOKUP(A65,Data2023!B$6:F$23,5,0) -> 677.53636 | S65: =I65*(J65+H65)*R65 -> 202184078 | T65: =S65+Q65+M65 -> 4.8796029e+08 | U65: =T65/G65 -> 1708.5444 | V65: =U65*V$6 -> 17.085444 | W65: =IF(G65<25000,500000,(G65/30000)*500000)/G65 -> 16.666667 | X65: =IF(C65<2,U65*17%,IF(C65<3,U65*16%,IF(C65<4,U65*15%,IF(C65<5,U65*14%,IF(C65<6,U65*13%,IF(C65<7,U65*12%,U65*11%)))))) -> 187.93989 | Y65: 1
A66: BOPP 18 mic | B66: =X66+W66+V66+U66 -> 1929.8574 | C66: 7 | D66: 0 | E66: 0 | F66: 1.02 | G66: =H66*F66 -> 290700 | H66: =H65+5000 -> 285000 | I66: =F66+0.02 -> 1.04 | J66: =IF(C66=8,1900,IF(C66=7,1800,IF(C66=6,1400,IF(C66=5,1200,IF(C66=4,900,IF(C66=3,800,IF(C66=2,500,400)))))))+H66/6000*50+IF(H66>40000,H66/40000*400,0) -> 7025 | K66: =(J66+H66)*I66 -> 303706 | L66: =C66*IF(A66="BOPP 18 mic",110,125)*Y66+(E66+D66) -> 770 | M66: =L66*(H66+J66)*I66 -> 233853620 | N66: =C66*20/60 -> 2.3333333 | O66: =IF(H66>40000,H66/40000+H66/7500,H66/7500) -> 45.125 | P66: 1200000 | Q66: =P66*(O66+N66) -> 56950000 | R66: =VLOOKUP(A66,Data2023!B$6:F$23,5,0) -> 677.53636 | S66: =I66*(J66+H66)*R66 -> 2.0577186e+08 | T66: =S66+Q66+M66 -> 4.9657548e+08 | U66: =T66/G66 -> 1708.206 | V66: =U66*V$6 -> 17.08206 | W66: =IF(G66<25000,500000,(G66/30000)*500000)/G66 -> 16.666667 | X66: =IF(C66<2,U66*17%,IF(C66<3,U66*16%,IF(C66<4,U66*15%,IF(C66<5,U66*14%,IF(C66<6,U66*13%,IF(C66<7,U66*12%,U66*11%)))))) -> 187.90266 | Y66: 1
A67: BOPP 18 mic | B67: =X67+W67+V67+U67 -> 1929.4914 | C67: 7 | D67: 0 | E67: 0 | F67: 1.02 | G67: =H67*F67 -> 295800 | H67: =H66+5000 -> 290000 | I67: =F67+0.02 -> 1.04 | J67: =IF(C67=8,1900,IF(C67=7,1800,IF(C67=6,1400,IF(C67=5,1200,IF(C67=4,900,IF(C67=3,800,IF(C67=2,500,400)))))))+H67/6000*50+IF(H67>40000,H67/40000*400,0) -> 7116.6667 | K67: =(J67+H67)*I67 -> 309001.33 | L67: =C67*IF(A67="BOPP 18 mic",110,125)*Y67+(E67+D67) -> 770 | M67: =L67*(H67+J67)*I67 -> 2.3793103e+08 | N67: =C67*20/60 -> 2.3333333 | O67: =IF(H67>40000,H67/40000+H67/7500,H67/7500) -> 45.916667 | P67: 1200000 | Q67: =P67*(O67+N67) -> 57900000 | R67: =VLOOKUP(A67,Data2023!B$6:F$23,5,0) -> 677.53636 | S67: =I67*(J67+H67)*R67 -> 2.0935964e+08 | T67: =S67+Q67+M67 -> 5.0519067e+08 | U67: =T67/G67 -> 1707.8792 | V67: =U67*V$6 -> 17.078792 | W67: =IF(G67<25000,500000,(G67/30000)*500000)/G67 -> 16.666667 | X67: =IF(C67<2,U67*17%,IF(C67<3,U67*16%,IF(C67<4,U67*15%,IF(C67<5,U67*14%,IF(C67<6,U67*13%,IF(C67<7,U67*12%,U67*11%)))))) -> 187.86671 | Y67: 1
A68: BOPP 18 mic | B68: =X68+W68+V68+U68 -> 3070.382 | C68: 4 | D68: 0 | E68: 0 | F68: 0.8 | G68: =H68*F68 -> 2400 | H68: 3000 | I68: =F68+0.02 -> 0.82 | J68: =IF(C68=8,1900,IF(C68=7,1800,IF(C68=6,1400,IF(C68=5,1200,IF(C68=4,900,IF(C68=3,800,IF(C68=2,500,400)))))))+H68/6000*50+IF(H68>40000,H68/40000*400,0) -> 925 | K68: =(J68+H68)*I68 -> 3218.5 | L68: =C68*IF(A68="BOPP 18 mic",110,125)*Y68+(E68+D68) -> 440 | M68: =L68*(H68+J68)*I68 -> 1416140 | N68: =C68*20/60 -> 1.3333333 | O68: =IF(H68>40000,H68/40000+H68/7500,H68/7500) -> 0.4 | P68: 1200000 | Q68: =P68*(O68+N68) -> 2080000 | R68: =VLOOKUP(A68,Data2023!B$6:F$23,5,0) -> 677.53636 | S68: =I68*(J68+H68)*R68 -> 2180650.8 | T68: =S68+Q68+M68 -> 5676790.8 | U68: =T68/G68 -> 2365.3295 | V68: =U68*V$6 -> 23.653295 | W68: =IF(G68<25000,500000,(G68/30000)*500000)/G68 -> 208.33333 | X68: =IF(C68<2,U68*17%,IF(C68<3,U68*16%,IF(C68<4,U68*20%,IF(C68<5,U68*20%,IF(C68<6,U68*13%,IF(C68<7,U68*12%,U68*11%)))))) -> 473.0659 | Y68: 1
A69: BOPP 18 mic | B69: =X69+W69+V69+U69 -> 2498.0591 | C69: =C68 -> 4 | D69: =D68 -> 0 | E69: =E68 -> 0 | F69: =F68 -> 0.8 | G69: =H69*F69 -> 4000 | H69: 5000 | I69: =F69+0.02 -> 0.82 | J69: =IF(C69=8,1900,IF(C69=7,1800,IF(C69=6,1400,IF(C69=5,1200,IF(C69=4,900,IF(C69=3,800,IF(C69=2,500,400)))))))+H69/6000*50+IF(H69>40000,H69/40000*400,0) -> 941.66667 | K69: =(J69+H69)*I69 -> 4872.1667 | L69: =C69*IF(A69="BOPP 18 mic",110,125)*Y69+(E69+D69) -> 440 | M69: =L69*(H69+J69)*I69 -> 2143753.3 | N69: =C69*20/60 -> 1.3333333 | O69: =IF(H69>40000,H69/40000+H69/7500,H69/7500) -> 0.66666667 | P69: 1200000 | Q69: =P69*(O69+N69) -> 2400000 | R69: =VLOOKUP(A69,Data2023!B$6:F$23,5,0) -> 677.53636 | S69: =I69*(J69+H69)*R69 -> 3301070.1 | T69: =S69+Q69+M69 -> 7844823.4 | U69: =T69/G69 -> 1961.2059 | V69: =U69*V$6 -> 19.612059 | W69: =IF(G69<25000,500000,(G69/30000)*500000)/G69 -> 125 | X69: =IF(C69<2,U69*17%,IF(C69<3,U69*16%,IF(C69<4,U69*20%,IF(C69<5,U69*20%,IF(C69<6,U69*13%,IF(C69<7,U69*12%,U69*11%)))))) -> 392.24117 | Y69: 1
A70: BOPP 18 mic | B70: =X70+W70+V70+U70 -> 2176.1274 | C70: =C69 -> 4 | D70: =D69 -> 0 | E70: =E69 -> 0 | F70: =F69 -> 0.8 | G70: =H70*F70 -> 6400 | H70: 8000 | I70: =F70+0.02 -> 0.82 | J70: =IF(C70=8,1900,IF(C70=7,1800,IF(C70=6,1400,IF(C70=5,1200,IF(C70=4,900,IF(C70=3,800,IF(C70=2,500,400)))))))+H70/6000*50+IF(H70>40000,H70/40000*400,0) -> 966.66667 | K70: =(J70+H70)*I70 -> 7352.6667 | L70: =C70*IF(A70="BOPP 18 mic",110,125)*Y70+(E70+D70) -> 440 | M70: =L70*(H70+J70)*I70 -> 3235173.3 | N70: =C70*20/60 -> 1.3333333 | O70: =IF(H70>40000,H70/40000+H70/7500,H70/7500) -> 1.0666667 | P70: 1200000 | Q70: =P70*(O70+N70) -> 2880000 | R70: =VLOOKUP(A70,Data2023!B$6:F$23,5,0) -> 677.53636 | S70: =I70*(J70+H70)*R70 -> 4981699 | T70: =S70+Q70+M70 -> 11096872 | U70: =T70/G70 -> 1733.8863 | V70: =U70*V$6 -> 17.338863 | W70: =IF(G70<25000,500000,(G70/30000)*500000)/G70 -> 78.125 | X70: =IF(C70<2,U70*17%,IF(C70<3,U70*16%,IF(C70<4,U70*20%,IF(C70<5,U70*20%,IF(C70<6,U70*13%,IF(C70<7,U70*12%,U70*11%)))))) -> 346.77726 | Y70: 1
A71: BOPP 18 mic | B71: =X71+W71+V71+U71 -> 2029.7949 | C71: =C70 -> 4 | D71: =D70 -> 0 | E71: =E70 -> 0 | F71: =F70 -> 0.8 | G71: =H71*F71 -> 8800 | H71: 11000 | I71: =F71+0.02 -> 0.82 | J71: =IF(C71=8,1900,IF(C71=7,1800,IF(C71=6,1400,IF(C71=5,1200,IF(C71=4,900,IF(C71=3,800,IF(C71=2,500,400)))))))+H71/6000*50+IF(H71>40000,H71/40000*400,0) -> 991.66667 | K71: =(J71+H71)*I71 -> 9833.1667 | L71: =C71*IF(A71="BOPP 18 mic",110,125)*Y71+(E71+D71) -> 440 | M71: =L71*(H71+J71)*I71 -> 4326593.3 | N71: =C71*20/60 -> 1.3333333 | O71: =IF(H71>40000,H71/40000+H71/7500,H71/7500) -> 1.4666667 | P71: 1200000 | Q71: =P71*(O71+N71) -> 3360000 | R71: =VLOOKUP(A71,Data2023!B$6:F$23,5,0) -> 677.53636 | S71: =I71*(J71+H71)*R71 -> 6662328 | T71: =S71+Q71+M71 -> 14348921 | U71: =T71/G71 -> 1630.5592 | V71: =U71*V$6 -> 16.305592 | W71: =IF(G71<25000,500000,(G71/30000)*500000)/G71 -> 56.818182 | X71: =IF(C71<2,U71*17%,IF(C71<3,U71*16%,IF(C71<4,U71*20%,IF(C71<5,U71*20%,IF(C71<6,U71*13%,IF(C71<7,U71*12%,U71*11%)))))) -> 326.11185 | Y71: 1
A72: BOPP 18 mic | B72: =X72+W72+V72+U72 -> 1854.1958 | C72: =C71 -> 4 | D72: =D71 -> 0 | E72: =E71 -> 0 | F72: =F71 -> 0.8 | G72: =H72*F72 -> 16000 | H72: 20000 | I72: =F72+0.02 -> 0.82 | J72: =IF(C72=8,1900,IF(C72=7,1800,IF(C72=6,1400,IF(C72=5,1200,IF(C72=4,900,IF(C72=3,800,IF(C72=2,500,400)))))))+H72/6000*50+IF(H72>40000,H72/40000*400,0) -> 1066.6667 | K72: =(J72+H72)*I72 -> 17274.667 | L72: =C72*IF(A72="BOPP 18 mic",110,125)*Y72+(E72+D72) -> 440 | M72: =L72*(H72+J72)*I72 -> 7600853.3 | N72: =C72*20/60 -> 1.3333333 | O72: =IF(H72>40000,H72/40000+H72/7500,H72/7500) -> 2.6666667 | P72: 1200000 | Q72: =P72*(O72+N72) -> 4800000 | R72: =VLOOKUP(A72,Data2023!B$6:F$23,5,0) -> 677.53636 | S72: =I72*(J72+H72)*R72 -> 11704215 | T72: =S72+Q72+M72 -> 24105068 | U72: =T72/G72 -> 1506.5668 | V72: =U72*V$6 -> 15.065668 | W72: =IF(G72<25000,500000,(G72/30000)*500000)/G72 -> 31.25 | X72: =IF(C72<2,U72*17%,IF(C72<3,U72*16%,IF(C72<4,U72*20%,IF(C72<5,U72*20%,IF(C72<6,U72*13%,IF(C72<7,U72*12%,U72*11%)))))) -> 301.31335 | Y72: 1
A73: BOPP 18 mic | B73: =X73+W73+V73+U73 -> 1761.0248 | C73: =C72 -> 4 | D73: =D72 -> 0 | E73: =E72 -> 0 | F73: =F72 -> 0.8 | G73: =H73*F73 -> 28000 | H73: 35000 | I73: =F73+0.02 -> 0.82 | J73: =IF(C73=8,1900,IF(C73=7,1800,IF(C73=6,1400,IF(C73=5,1200,IF(C73=4,900,IF(C73=3,800,IF(C73=2,500,400)))))))+H73/6000*50+IF(H73>40000,H73/40000*400,0) -> 1191.6667 | K73: =(J73+H73)*I73 -> 29677.167 | L73: =C73*IF(A73="BOPP 18 mic",110,125)*Y73+(E73+D73) -> 440 | M73: =L73*(H73+J73)*I73 -> 13057953 | N73: =C73*20/60 -> 1.3333333 | O73: =IF(H73>40000,H73/40000+H73/7500,H73/7500) -> 4.6666667 | P73: 1200000 | Q73: =P73*(O73+N73) -> 7200000 | R73: =VLOOKUP(A73,Data2023!B$6:F$23,5,0) -> 677.53636 | S73: =I73*(J73+H73)*R73 -> 20107360 | T73: =S73+Q73+M73 -> 40365313 | U73: =T73/G73 -> 1441.6183 | V73: =U73*V$6 -> 14.416183 | W73: =IF(G73<25000,500000,(G73/30000)*500000)/G73 -> 16.666667 | X73: =IF(C73<2,U73*17%,IF(C73<3,U73*16%,IF(C73<4,U73*20%,IF(C73<5,U73*20%,IF(C73<6,U73*13%,IF(C73<7,U73*12%,U73*11%)))))) -> 288.32366 | Y73: 1
...
